[2025-02-04T01:35:48.568+0000] {local_task_job_runner.py:123} INFO - ::group::Pre task execution logs
[2025-02-04T01:35:48.589+0000] {taskinstance.py:2613} INFO - Dependencies all met for dep_context=non-requeueable deps ti=<TaskInstance: dbt_pipeline.run_dbt manual__2025-02-04T01:35:47.606760+00:00 [queued]>
[2025-02-04T01:35:48.597+0000] {taskinstance.py:2613} INFO - Dependencies all met for dep_context=requeueable deps ti=<TaskInstance: dbt_pipeline.run_dbt manual__2025-02-04T01:35:47.606760+00:00 [queued]>
[2025-02-04T01:35:48.598+0000] {taskinstance.py:2866} INFO - Starting attempt 1 of 1
[2025-02-04T01:35:48.614+0000] {taskinstance.py:2889} INFO - Executing <Task(BashOperator): run_dbt> on 2025-02-04 01:35:47.606760+00:00
[2025-02-04T01:35:48.620+0000] {logging_mixin.py:190} WARNING - /home/airflow/.local/lib/python3.12/site-packages/airflow/task/task_runner/standard_task_runner.py:70 DeprecationWarning: This process (pid=231) is multi-threaded, use of fork() may lead to deadlocks in the child.
[2025-02-04T01:35:48.621+0000] {standard_task_runner.py:72} INFO - Started process 236 to run task
[2025-02-04T01:35:48.621+0000] {standard_task_runner.py:104} INFO - Running: ['airflow', 'tasks', 'run', 'dbt_pipeline', 'run_dbt', 'manual__2025-02-04T01:35:47.606760+00:00', '--job-id', '3', '--raw', '--subdir', 'DAGS_FOLDER/dbt_dag.py', '--cfg-path', '/tmp/tmpgz4879uw']
[2025-02-04T01:35:48.624+0000] {standard_task_runner.py:105} INFO - Job 3: Subtask run_dbt
[2025-02-04T01:35:48.640+0000] {logging_mixin.py:190} WARNING - /home/airflow/.local/lib/python3.12/site-packages/airflow/settings.py:209 DeprecationWarning: The sql_alchemy_conn option in [core] has been moved to the sql_alchemy_conn option in [database] - the old setting has been used, but please update your config.
[2025-02-04T01:35:48.673+0000] {task_command.py:467} INFO - Running <TaskInstance: dbt_pipeline.run_dbt manual__2025-02-04T01:35:47.606760+00:00 [running]> on host 57157ff74342
[2025-02-04T01:35:48.747+0000] {taskinstance.py:3132} INFO - Exporting env vars: AIRFLOW_CTX_DAG_OWNER='airflow' AIRFLOW_CTX_DAG_ID='dbt_pipeline' AIRFLOW_CTX_TASK_ID='run_dbt' AIRFLOW_CTX_EXECUTION_DATE='2025-02-04T01:35:47.606760+00:00' AIRFLOW_CTX_TRY_NUMBER='1' AIRFLOW_CTX_DAG_RUN_ID='manual__2025-02-04T01:35:47.606760+00:00'
[2025-02-04T01:35:48.748+0000] {taskinstance.py:731} INFO - ::endgroup::
[2025-02-04T01:35:48.764+0000] {subprocess.py:78} INFO - Tmp dir root location: /tmp
[2025-02-04T01:35:48.765+0000] {subprocess.py:88} INFO - Running command: ['/usr/bin/bash', '-c', 'docker exec dbt dbt run']
[2025-02-04T01:35:48.771+0000] {subprocess.py:99} INFO - Output:
[2025-02-04T01:35:50.705+0000] {subprocess.py:106} INFO - [0m01:35:50  Running with dbt=1.9.2
[2025-02-04T01:35:50.986+0000] {subprocess.py:106} INFO - [0m01:35:50  Registered adapter: postgres=1.9.0
[2025-02-04T01:35:51.073+0000] {subprocess.py:106} INFO - [0m01:35:51  Unable to do partial parsing because saved manifest not found. Starting full parse.
[2025-02-04T01:35:52.454+0000] {subprocess.py:106} INFO - [0m01:35:52  Found 2 models, 431 macros
[2025-02-04T01:35:52.456+0000] {subprocess.py:106} INFO - [0m01:35:52
[2025-02-04T01:35:52.457+0000] {subprocess.py:106} INFO - [0m01:35:52  Concurrency: 4 threads (target='dev')
[2025-02-04T01:35:52.457+0000] {subprocess.py:106} INFO - [0m01:35:52
[2025-02-04T01:35:52.624+0000] {subprocess.py:106} INFO - [0m01:35:52  1 of 2 START sql view model public.stg_payment_amount .......................... [RUN]
[2025-02-04T01:35:52.746+0000] {subprocess.py:106} INFO - [0m01:35:52  1 of 2 OK created sql view model public.stg_payment_amount ..................... [[32mCREATE VIEW[0m in 0.12s]
[2025-02-04T01:35:52.751+0000] {subprocess.py:106} INFO - [0m01:35:52  2 of 2 START sql table model public.payment_amount ............................. [RUN]
[2025-02-04T01:35:52.830+0000] {subprocess.py:106} INFO - [0m01:35:52  2 of 2 OK created sql table model public.payment_amount ........................ [[32mSELECT 239[0m in 0.08s]
[2025-02-04T01:35:52.844+0000] {subprocess.py:106} INFO - [0m01:35:52
[2025-02-04T01:35:52.845+0000] {subprocess.py:106} INFO - [0m01:35:52  Finished running 1 table model, 1 view model in 0 hours 0 minutes and 0.39 seconds (0.39s).
[2025-02-04T01:35:52.877+0000] {subprocess.py:106} INFO - [0m01:35:52
[2025-02-04T01:35:52.877+0000] {subprocess.py:106} INFO - [0m01:35:52  [32mCompleted successfully[0m
[2025-02-04T01:35:52.878+0000] {subprocess.py:106} INFO - [0m01:35:52
[2025-02-04T01:35:52.878+0000] {subprocess.py:106} INFO - [0m01:35:52  Done. PASS=2 WARN=0 ERROR=0 SKIP=0 TOTAL=2
[2025-02-04T01:35:53.674+0000] {subprocess.py:110} INFO - Command exited with return code 137
[2025-02-04T01:35:53.692+0000] {taskinstance.py:3311} ERROR - Task failed with exception
Traceback (most recent call last):
  File "/home/airflow/.local/lib/python3.12/site-packages/airflow/models/taskinstance.py", line 767, in _execute_task
    result = _execute_callable(context=context, **execute_callable_kwargs)
             ^^^^^^^^^^^^^^^^^^^^^^^^^^^^^^^^^^^^^^^^^^^^^^^^^^^^^^^^^^^^^
  File "/home/airflow/.local/lib/python3.12/site-packages/airflow/models/taskinstance.py", line 733, in _execute_callable
    return ExecutionCallableRunner(
           ^^^^^^^^^^^^^^^^^^^^^^^^
  File "/home/airflow/.local/lib/python3.12/site-packages/airflow/utils/operator_helpers.py", line 252, in run
    return self.func(*args, **kwargs)
           ^^^^^^^^^^^^^^^^^^^^^^^^^^
  File "/home/airflow/.local/lib/python3.12/site-packages/airflow/models/baseoperator.py", line 422, in wrapper
    return func(self, *args, **kwargs)
           ^^^^^^^^^^^^^^^^^^^^^^^^^^^
  File "/home/airflow/.local/lib/python3.12/site-packages/airflow/operators/bash.py", line 276, in execute
    raise AirflowException(
airflow.exceptions.AirflowException: Bash command failed. The command returned a non-zero exit code 137.
[2025-02-04T01:35:53.699+0000] {taskinstance.py:1225} INFO - Marking task as FAILED. dag_id=dbt_pipeline, task_id=run_dbt, run_id=manual__2025-02-04T01:35:47.606760+00:00, execution_date=20250204T013547, start_date=20250204T013548, end_date=20250204T013553
[2025-02-04T01:35:53.710+0000] {taskinstance.py:340} INFO - ::group::Post task execution logs
[2025-02-04T01:35:53.711+0000] {standard_task_runner.py:124} ERROR - Failed to execute job 3 for task run_dbt (Bash command failed. The command returned a non-zero exit code 137.; 236)
Traceback (most recent call last):
  File "/home/airflow/.local/lib/python3.12/site-packages/airflow/task/task_runner/standard_task_runner.py", line 117, in _start_by_fork
    ret = args.func(args, dag=self.dag)
          ^^^^^^^^^^^^^^^^^^^^^^^^^^^^^
  File "/home/airflow/.local/lib/python3.12/site-packages/airflow/cli/cli_config.py", line 49, in command
    return func(*args, **kwargs)
           ^^^^^^^^^^^^^^^^^^^^^
  File "/home/airflow/.local/lib/python3.12/site-packages/airflow/utils/cli.py", line 116, in wrapper
    return f(*args, **kwargs)
           ^^^^^^^^^^^^^^^^^^
  File "/home/airflow/.local/lib/python3.12/site-packages/airflow/cli/commands/task_command.py", line 483, in task_run
    task_return_code = _run_task_by_selected_method(args, _dag, ti)
                       ^^^^^^^^^^^^^^^^^^^^^^^^^^^^^^^^^^^^^^^^^^^^
  File "/home/airflow/.local/lib/python3.12/site-packages/airflow/cli/commands/task_command.py", line 256, in _run_task_by_selected_method
    return _run_raw_task(args, ti)
           ^^^^^^^^^^^^^^^^^^^^^^^
  File "/home/airflow/.local/lib/python3.12/site-packages/airflow/cli/commands/task_command.py", line 341, in _run_raw_task
    return ti._run_raw_task(
           ^^^^^^^^^^^^^^^^^
  File "/home/airflow/.local/lib/python3.12/site-packages/airflow/utils/session.py", line 97, in wrapper
    return func(*args, session=session, **kwargs)
           ^^^^^^^^^^^^^^^^^^^^^^^^^^^^^^^^^^^^^^
  File "/home/airflow/.local/lib/python3.12/site-packages/airflow/models/taskinstance.py", line 3005, in _run_raw_task
    return _run_raw_task(
           ^^^^^^^^^^^^^^
  File "/home/airflow/.local/lib/python3.12/site-packages/airflow/models/taskinstance.py", line 273, in _run_raw_task
    TaskInstance._execute_task_with_callbacks(
  File "/home/airflow/.local/lib/python3.12/site-packages/airflow/models/taskinstance.py", line 3159, in _execute_task_with_callbacks
    result = self._execute_task(context, task_orig)
             ^^^^^^^^^^^^^^^^^^^^^^^^^^^^^^^^^^^^^^
  File "/home/airflow/.local/lib/python3.12/site-packages/airflow/models/taskinstance.py", line 3183, in _execute_task
    return _execute_task(self, context, task_orig)
           ^^^^^^^^^^^^^^^^^^^^^^^^^^^^^^^^^^^^^^^
  File "/home/airflow/.local/lib/python3.12/site-packages/airflow/models/taskinstance.py", line 767, in _execute_task
    result = _execute_callable(context=context, **execute_callable_kwargs)
             ^^^^^^^^^^^^^^^^^^^^^^^^^^^^^^^^^^^^^^^^^^^^^^^^^^^^^^^^^^^^^
  File "/home/airflow/.local/lib/python3.12/site-packages/airflow/models/taskinstance.py", line 733, in _execute_callable
    return ExecutionCallableRunner(
           ^^^^^^^^^^^^^^^^^^^^^^^^
  File "/home/airflow/.local/lib/python3.12/site-packages/airflow/utils/operator_helpers.py", line 252, in run
    return self.func(*args, **kwargs)
           ^^^^^^^^^^^^^^^^^^^^^^^^^^
  File "/home/airflow/.local/lib/python3.12/site-packages/airflow/models/baseoperator.py", line 422, in wrapper
    return func(self, *args, **kwargs)
           ^^^^^^^^^^^^^^^^^^^^^^^^^^^
  File "/home/airflow/.local/lib/python3.12/site-packages/airflow/operators/bash.py", line 276, in execute
    raise AirflowException(
airflow.exceptions.AirflowException: Bash command failed. The command returned a non-zero exit code 137.
[2025-02-04T01:35:53.744+0000] {local_task_job_runner.py:266} INFO - Task exited with return code 1
[2025-02-04T01:35:53.764+0000] {taskinstance.py:3895} INFO - 0 downstream tasks scheduled from follow-on schedule check
[2025-02-04T01:35:53.766+0000] {local_task_job_runner.py:245} INFO - ::endgroup::
